<robot
  name="0320_all_assembly">
  <link name="dummy">
  </link>
  <link
    name="base_link">
    <inertial>
      <origin
        xyz="-0.000756319161576836 -0.0916302735623335 0.00312344416944757"
        rpy="0 0 0" />
      <mass
        value="0.019899935517462" />
      <inertia
        ixx="1.88663880803478E-05"
        ixy="2.11655934416254E-06"
        ixz="4.15041155919205E-07"
        iyy="2.1804609783136E-06"
        iyz="-2.85101666775227E-06"
        izz="1.86626954662574E-05" />
    </inertial>
    <visual>
      <origin
        xyz="0 0 0"
        rpy="0 0 0" />
      <geometry>
        <mesh
          filename="package://0320_all_assembly/meshes/base_link.STL" />
      </geometry>
      <material
        name="">
        <color
          rgba="0.792156862745098 0.819607843137255 0.933333333333333 1" />
      </material>
    </visual>
    <collision>
      <origin
        xyz="0 0 0"
        rpy="0 0 0" />
      <geometry>
        <mesh
          filename="package://0320_all_assembly/meshes/base_link.STL" />
      </geometry>
    </collision>
  </link>
  <joint name="dummy_joint" type="fixed">
    <parent link="dummy"/>
    <child link="base_link"/>
  </joint>
  <link
    name="l1">
    <inertial>
      <origin
        xyz="0.0145783504141991 0.015286115724238 -0.046579726437659"
        rpy="0 0 0" />
      <mass
        value="0.019899935517462" />
      <inertia
        ixx="1.88663880803478E-05"
        ixy="4.15041155919205E-07"
        ixz="-2.11655934416254E-06"
        iyy="1.86626954662574E-05"
        iyz="2.85101666775228E-06"
        izz="2.18046097831359E-06" />
    </inertial>
    <visual>
      <origin
        xyz="0 0 0"
        rpy="0 0 0" />
      <geometry>
        <mesh
          filename="package://0320_all_assembly/meshes/l1.STL" />
      </geometry>
      <material
        name="">
        <color
          rgba="0.792156862745098 0.819607843137255 0.933333333333333 1" />
      </material>
    </visual>
    <collision>
      <origin
        xyz="0 0 0"
        rpy="0 0 0" />
      <geometry>
        <mesh
          filename="package://0320_all_assembly/meshes/l1.STL" />
      </geometry>
    </collision>
  </link>
  <joint
    name="j1"
    type="revolute">
    <origin
      xyz="-0.0047142 -0.06651 0.0095873"
      rpy="1.5708 6.7654E-15 -3.1416" />
    <parent
      link="base_link" />
    <child
      link="l1" />
    <axis
      xyz="1 0 0" />
    <limit
      lower="0"
      upper="3.14"
      effort="0"
      velocity="0" />
  </joint>
  <link
    name="l2">
    <inertial>
      <origin
        xyz="-0.00856875783176582 -0.00806117546357141 -0.00968051470400746"
        rpy="0 0 0" />
      <mass
        value="0.00625564379675455" />
      <inertia
        ixx="1.26026701897412E-06"
        ixy="7.10216697853826E-08"
        ixz="1.30374282427878E-07"
        iyy="1.17452756198058E-06"
        iyz="-9.94146108547723E-08"
        izz="3.17482320639255E-07" />
    </inertial>
    <visual>
      <origin
        xyz="0 0 0"
        rpy="0 0 0" />
      <geometry>
        <mesh
          filename="package://0320_all_assembly/meshes/l2.STL" />
      </geometry>
      <material
        name="">
        <color
          rgba="0.792156862745098 0.819607843137255 0.933333333333333 1" />
      </material>
    </visual>
    <collision>
      <origin
        xyz="0 0 0"
        rpy="0 0 0" />
      <geometry>
        <mesh
          filename="package://0320_all_assembly/meshes/l2.STL" />
      </geometry>
    </collision>
  </link>
  <joint
    name="j2"
    type="revolute">
    <origin
      xyz="0 0.02175 -0.0717"
      rpy="3.1416 1.121E-44 1.5777E-30" />
    <parent
      link="l1" />
    <child
      link="l2" />
    <axis
      xyz="-1 0 0" />
    <limit
      lower="0"
      upper="3.14"
      effort="0"
      velocity="0" />
  </joint>
</robot>
